(0.008) SELECT "django_session"."session_key", "django_session"."session_data", "django_session"."expire_date" FROM "django_session" WHERE ("django_session"."expire_date" > '2020-04-14 15:05:12.168016' AND "django_session"."session_key" = 'hw9blldrir5yobtxyx7w97e2c0sci8eu'); args=('2020-04-14 15:05:12.168016', 'hw9blldrir5yobtxyx7w97e2c0sci8eu')
(0.001) SELECT "auth_user"."id", "auth_user"."password", "auth_user"."last_login", "auth_user"."is_superuser", "auth_user"."username", "auth_user"."first_name", "auth_user"."last_name", "auth_user"."email", "auth_user"."is_staff", "auth_user"."is_active", "auth_user"."date_joined" FROM "auth_user" WHERE "auth_user"."username" IS NULL; args=()
(0.000) SELECT "auth_user"."id", "auth_user"."password", "auth_user"."last_login", "auth_user"."is_superuser", "auth_user"."username", "auth_user"."first_name", "auth_user"."last_name", "auth_user"."email", "auth_user"."is_staff", "auth_user"."is_active", "auth_user"."date_joined" FROM "auth_user" WHERE "auth_user"."username" = 'g.hautecoeur'; args=('g.hautecoeur',)
(0.000) BEGIN; args=None
(0.000) INSERT INTO "auth_user" ("password", "last_login", "is_superuser", "username", "first_name", "last_name", "email", "is_staff", "is_active", "date_joined") VALUES ('', NULL, 0, 'g.hautecoeur', '', '', '', 0, 1, '2020-04-14 15:05:42.648968'); args=['', None, False, 'g.hautecoeur', '', '', '', False, True, '2020-04-14 15:05:42.648968']
(0.000) SELECT (1) AS "a" FROM "django_session" WHERE "django_session"."session_key" = 'iplai4vas8lv0un5snt7wmrnhsj8szd4'  LIMIT 1; args=('iplai4vas8lv0un5snt7wmrnhsj8szd4',)
(0.000) BEGIN; args=None
(0.000) INSERT INTO "django_session" ("session_key", "session_data", "expire_date") SELECT 'iplai4vas8lv0un5snt7wmrnhsj8szd4', 'NGVlZmE1OGQ1NjcwMDI2YTYxMmQyNDVhMTgwMjE5OTY3NmRhMzAxODp7fQ==', '2020-04-28 15:05:42.714583'; args=('iplai4vas8lv0un5snt7wmrnhsj8szd4', 'NGVlZmE1OGQ1NjcwMDI2YTYxMmQyNDVhMTgwMjE5OTY3NmRhMzAxODp7fQ==', '2020-04-28 15:05:42.714583')
(0.000) BEGIN; args=None
(0.000) UPDATE "auth_user" SET "last_login" = '2020-04-14 15:05:42.756422' WHERE "auth_user"."id" = 1; args=('2020-04-14 15:05:42.756422', 1)
(0.000) SELECT (1) AS "a" FROM "django_session" WHERE "django_session"."session_key" = 'iplai4vas8lv0un5snt7wmrnhsj8szd4'  LIMIT 1; args=('iplai4vas8lv0un5snt7wmrnhsj8szd4',)
(0.000) SELECT "django_cas_ng_sessionticket"."id", "django_cas_ng_sessionticket"."session_key", "django_cas_ng_sessionticket"."ticket" FROM "django_cas_ng_sessionticket" WHERE "django_cas_ng_sessionticket"."session_key" = 'iplai4vas8lv0un5snt7wmrnhsj8szd4'; args=('iplai4vas8lv0un5snt7wmrnhsj8szd4',)
(0.000) BEGIN; args=None
(0.013) INSERT INTO "django_cas_ng_sessionticket" ("session_key", "ticket") VALUES ('iplai4vas8lv0un5snt7wmrnhsj8szd4', 'ST-7843318-FmzOZzhD7u1zER275aq7-ssocas.isae.fr'); args=['iplai4vas8lv0un5snt7wmrnhsj8szd4', 'ST-7843318-FmzOZzhD7u1zER275aq7-ssocas.isae.fr']
(0.000) BEGIN; args=None
(0.000) UPDATE "django_session" SET "session_data" = 'YTNkYzg2YjBlZjc3ODE5Y2IyZjlmMzMzODdkYjBjMTdjNGFjYjZmOTp7Il9hdXRoX3VzZXJfaWQiOiIxIiwiX2F1dGhfdXNlcl9iYWNrZW5kIjoiZGphbmdvX2Nhc19uZy5iYWNrZW5kcy5DQVNCYWNrZW5kIiwiX2F1dGhfdXNlcl9oYXNoIjoiN2I2OTY1YWJlMDczNzBiNmUwYjM0NjU5ZGY1ZDM3MWMyN2Y1MTY5YSJ9', "expire_date" = '2020-04-28 15:05:42.852101' WHERE "django_session"."session_key" = 'iplai4vas8lv0un5snt7wmrnhsj8szd4'; args=('YTNkYzg2YjBlZjc3ODE5Y2IyZjlmMzMzODdkYjBjMTdjNGFjYjZmOTp7Il9hdXRoX3VzZXJfaWQiOiIxIiwiX2F1dGhfdXNlcl9iYWNrZW5kIjoiZGphbmdvX2Nhc19uZy5iYWNrZW5kcy5DQVNCYWNrZW5kIiwiX2F1dGhfdXNlcl9oYXNoIjoiN2I2OTY1YWJlMDczNzBiNmUwYjM0NjU5ZGY1ZDM3MWMyN2Y1MTY5YSJ9', '2020-04-28 15:05:42.852101', 'iplai4vas8lv0un5snt7wmrnhsj8szd4')
(0.009) SELECT "django_session"."session_key", "django_session"."session_data", "django_session"."expire_date" FROM "django_session" WHERE ("django_session"."expire_date" > '2020-04-14 15:05:42.939070' AND "django_session"."session_key" = 'iplai4vas8lv0un5snt7wmrnhsj8szd4'); args=('2020-04-14 15:05:42.939070', 'iplai4vas8lv0un5snt7wmrnhsj8szd4')
(0.000) SELECT "auth_user"."id", "auth_user"."password", "auth_user"."last_login", "auth_user"."is_superuser", "auth_user"."username", "auth_user"."first_name", "auth_user"."last_name", "auth_user"."email", "auth_user"."is_staff", "auth_user"."is_active", "auth_user"."date_joined" FROM "auth_user" WHERE "auth_user"."id" = 1; args=(1,)
(0.001) SELECT "django_session"."session_key", "django_session"."session_data", "django_session"."expire_date" FROM "django_session" WHERE ("django_session"."expire_date" > '2020-04-14 15:05:51.521361' AND "django_session"."session_key" = 'iplai4vas8lv0un5snt7wmrnhsj8szd4'); args=('2020-04-14 15:05:51.521361', 'iplai4vas8lv0un5snt7wmrnhsj8szd4')
(0.000) SELECT "auth_user"."id", "auth_user"."password", "auth_user"."last_login", "auth_user"."is_superuser", "auth_user"."username", "auth_user"."first_name", "auth_user"."last_name", "auth_user"."email", "auth_user"."is_staff", "auth_user"."is_active", "auth_user"."date_joined" FROM "auth_user" WHERE "auth_user"."id" = 1; args=(1,)
Exception while resolving variable 'id' in template 'dash/lms_view.html'.
Traceback (most recent call last):
  File "/opt/xStats/venv/lib64/python3.6/site-packages/django/utils/datastructures.py", line 77, in __getitem__
    list_ = super().__getitem__(key)
KeyError: 'id'

During handling of the above exception, another exception occurred:

Traceback (most recent call last):
  File "/opt/xStats/venv/lib64/python3.6/site-packages/django/template/base.py", line 829, in _resolve_lookup
    current = current[bit]
  File "/opt/xStats/venv/lib64/python3.6/site-packages/django/utils/datastructures.py", line 79, in __getitem__
    raise MultiValueDictKeyError(key)
django.utils.datastructures.MultiValueDictKeyError: 'id'

During handling of the above exception, another exception occurred:

Traceback (most recent call last):
  File "/opt/xStats/venv/lib64/python3.6/site-packages/django/template/base.py", line 837, in _resolve_lookup
    current = getattr(current, bit)
AttributeError: 'QueryDict' object has no attribute 'id'

During handling of the above exception, another exception occurred:

Traceback (most recent call last):
  File "/opt/xStats/venv/lib64/python3.6/site-packages/django/template/base.py", line 843, in _resolve_lookup
    current = current[int(bit)]
ValueError: invalid literal for int() with base 10: 'id'

During handling of the above exception, another exception occurred:

Traceback (most recent call last):
  File "/opt/xStats/venv/lib64/python3.6/site-packages/django/template/base.py", line 850, in _resolve_lookup
    (bit, current))  # missing attribute
django.template.base.VariableDoesNotExist: Failed lookup for key [id] in <QueryDict: {}>
(0.001) SELECT "django_session"."session_key", "django_session"."session_data", "django_session"."expire_date" FROM "django_session" WHERE ("django_session"."expire_date" > '2020-04-15 08:16:09.526323' AND "django_session"."session_key" = 'iplai4vas8lv0un5snt7wmrnhsj8szd4'); args=('2020-04-15 08:16:09.526323', 'iplai4vas8lv0un5snt7wmrnhsj8szd4')
(0.000) SELECT "auth_user"."id", "auth_user"."password", "auth_user"."last_login", "auth_user"."is_superuser", "auth_user"."username", "auth_user"."first_name", "auth_user"."last_name", "auth_user"."email", "auth_user"."is_staff", "auth_user"."is_active", "auth_user"."date_joined" FROM "auth_user" WHERE "auth_user"."id" = 1; args=(1,)
Exception while resolving variable 'id' in template 'dash/lms_view.html'.
Traceback (most recent call last):
  File "/opt/xStats/venv/lib64/python3.6/site-packages/django/utils/datastructures.py", line 77, in __getitem__
    list_ = super().__getitem__(key)
KeyError: 'id'

During handling of the above exception, another exception occurred:

Traceback (most recent call last):
  File "/opt/xStats/venv/lib64/python3.6/site-packages/django/template/base.py", line 829, in _resolve_lookup
    current = current[bit]
  File "/opt/xStats/venv/lib64/python3.6/site-packages/django/utils/datastructures.py", line 79, in __getitem__
    raise MultiValueDictKeyError(key)
django.utils.datastructures.MultiValueDictKeyError: 'id'

During handling of the above exception, another exception occurred:

Traceback (most recent call last):
  File "/opt/xStats/venv/lib64/python3.6/site-packages/django/template/base.py", line 837, in _resolve_lookup
    current = getattr(current, bit)
AttributeError: 'QueryDict' object has no attribute 'id'

During handling of the above exception, another exception occurred:

Traceback (most recent call last):
  File "/opt/xStats/venv/lib64/python3.6/site-packages/django/template/base.py", line 843, in _resolve_lookup
    current = current[int(bit)]
ValueError: invalid literal for int() with base 10: 'id'

During handling of the above exception, another exception occurred:

Traceback (most recent call last):
  File "/opt/xStats/venv/lib64/python3.6/site-packages/django/template/base.py", line 850, in _resolve_lookup
    (bit, current))  # missing attribute
django.template.base.VariableDoesNotExist: Failed lookup for key [id] in <QueryDict: {}>
(0.001) SELECT "django_session"."session_key", "django_session"."session_data", "django_session"."expire_date" FROM "django_session" WHERE ("django_session"."expire_date" > '2020-04-15 08:55:24.639569' AND "django_session"."session_key" = 'iplai4vas8lv0un5snt7wmrnhsj8szd4'); args=('2020-04-15 08:55:24.639569', 'iplai4vas8lv0un5snt7wmrnhsj8szd4')
(0.000) SELECT "auth_user"."id", "auth_user"."password", "auth_user"."last_login", "auth_user"."is_superuser", "auth_user"."username", "auth_user"."first_name", "auth_user"."last_name", "auth_user"."email", "auth_user"."is_staff", "auth_user"."is_active", "auth_user"."date_joined" FROM "auth_user" WHERE "auth_user"."id" = 1; args=(1,)
Exception while resolving variable 'id' in template 'dash/lms_view.html'.
Traceback (most recent call last):
  File "/opt/xStats/venv/lib64/python3.6/site-packages/django/utils/datastructures.py", line 77, in __getitem__
    list_ = super().__getitem__(key)
KeyError: 'id'

During handling of the above exception, another exception occurred:

Traceback (most recent call last):
  File "/opt/xStats/venv/lib64/python3.6/site-packages/django/template/base.py", line 829, in _resolve_lookup
    current = current[bit]
  File "/opt/xStats/venv/lib64/python3.6/site-packages/django/utils/datastructures.py", line 79, in __getitem__
    raise MultiValueDictKeyError(key)
django.utils.datastructures.MultiValueDictKeyError: 'id'

During handling of the above exception, another exception occurred:

Traceback (most recent call last):
  File "/opt/xStats/venv/lib64/python3.6/site-packages/django/template/base.py", line 837, in _resolve_lookup
    current = getattr(current, bit)
AttributeError: 'QueryDict' object has no attribute 'id'

During handling of the above exception, another exception occurred:

Traceback (most recent call last):
  File "/opt/xStats/venv/lib64/python3.6/site-packages/django/template/base.py", line 843, in _resolve_lookup
    current = current[int(bit)]
ValueError: invalid literal for int() with base 10: 'id'

During handling of the above exception, another exception occurred:

Traceback (most recent call last):
  File "/opt/xStats/venv/lib64/python3.6/site-packages/django/template/base.py", line 850, in _resolve_lookup
    (bit, current))  # missing attribute
django.template.base.VariableDoesNotExist: Failed lookup for key [id] in <QueryDict: {}>
Exception while resolving variable 'id' in template 'dash/lms_view.html'.
Traceback (most recent call last):
  File "/opt/xStats/venv/lib64/python3.6/site-packages/django/utils/datastructures.py", line 77, in __getitem__
    list_ = super().__getitem__(key)
KeyError: 'id'

During handling of the above exception, another exception occurred:

Traceback (most recent call last):
  File "/opt/xStats/venv/lib64/python3.6/site-packages/django/template/base.py", line 829, in _resolve_lookup
    current = current[bit]
  File "/opt/xStats/venv/lib64/python3.6/site-packages/django/utils/datastructures.py", line 79, in __getitem__
    raise MultiValueDictKeyError(key)
django.utils.datastructures.MultiValueDictKeyError: 'id'

During handling of the above exception, another exception occurred:

Traceback (most recent call last):
  File "/opt/xStats/venv/lib64/python3.6/site-packages/django/template/base.py", line 837, in _resolve_lookup
    current = getattr(current, bit)
AttributeError: 'QueryDict' object has no attribute 'id'

During handling of the above exception, another exception occurred:

Traceback (most recent call last):
  File "/opt/xStats/venv/lib64/python3.6/site-packages/django/template/base.py", line 843, in _resolve_lookup
    current = current[int(bit)]
ValueError: invalid literal for int() with base 10: 'id'

During handling of the above exception, another exception occurred:

Traceback (most recent call last):
  File "/opt/xStats/venv/lib64/python3.6/site-packages/django/template/base.py", line 850, in _resolve_lookup
    (bit, current))  # missing attribute
django.template.base.VariableDoesNotExist: Failed lookup for key [id] in <QueryDict: {}>
Exception while resolving variable 'id' in template 'dash/lms_view.html'.
Traceback (most recent call last):
  File "/opt/xStats/venv/lib64/python3.6/site-packages/django/utils/datastructures.py", line 77, in __getitem__
    list_ = super().__getitem__(key)
KeyError: 'id'

During handling of the above exception, another exception occurred:

Traceback (most recent call last):
  File "/opt/xStats/venv/lib64/python3.6/site-packages/django/template/base.py", line 829, in _resolve_lookup
    current = current[bit]
  File "/opt/xStats/venv/lib64/python3.6/site-packages/django/utils/datastructures.py", line 79, in __getitem__
    raise MultiValueDictKeyError(key)
django.utils.datastructures.MultiValueDictKeyError: 'id'

During handling of the above exception, another exception occurred:

Traceback (most recent call last):
  File "/opt/xStats/venv/lib64/python3.6/site-packages/django/template/base.py", line 837, in _resolve_lookup
    current = getattr(current, bit)
AttributeError: 'QueryDict' object has no attribute 'id'

During handling of the above exception, another exception occurred:

Traceback (most recent call last):
  File "/opt/xStats/venv/lib64/python3.6/site-packages/django/template/base.py", line 843, in _resolve_lookup
    current = current[int(bit)]
ValueError: invalid literal for int() with base 10: 'id'

During handling of the above exception, another exception occurred:

Traceback (most recent call last):
  File "/opt/xStats/venv/lib64/python3.6/site-packages/django/template/base.py", line 850, in _resolve_lookup
    (bit, current))  # missing attribute
django.template.base.VariableDoesNotExist: Failed lookup for key [id] in <QueryDict: {}>
Exception while resolving variable 'id' in template 'dash/lms_view.html'.
Traceback (most recent call last):
  File "/opt/xStats/venv/lib64/python3.6/site-packages/django/utils/datastructures.py", line 77, in __getitem__
    list_ = super().__getitem__(key)
KeyError: 'id'

During handling of the above exception, another exception occurred:

Traceback (most recent call last):
  File "/opt/xStats/venv/lib64/python3.6/site-packages/django/template/base.py", line 829, in _resolve_lookup
    current = current[bit]
  File "/opt/xStats/venv/lib64/python3.6/site-packages/django/utils/datastructures.py", line 79, in __getitem__
    raise MultiValueDictKeyError(key)
django.utils.datastructures.MultiValueDictKeyError: 'id'

During handling of the above exception, another exception occurred:

Traceback (most recent call last):
  File "/opt/xStats/venv/lib64/python3.6/site-packages/django/template/base.py", line 837, in _resolve_lookup
    current = getattr(current, bit)
AttributeError: 'QueryDict' object has no attribute 'id'

During handling of the above exception, another exception occurred:

Traceback (most recent call last):
  File "/opt/xStats/venv/lib64/python3.6/site-packages/django/template/base.py", line 843, in _resolve_lookup
    current = current[int(bit)]
ValueError: invalid literal for int() with base 10: 'id'

During handling of the above exception, another exception occurred:

Traceback (most recent call last):
  File "/opt/xStats/venv/lib64/python3.6/site-packages/django/template/base.py", line 850, in _resolve_lookup
    (bit, current))  # missing attribute
django.template.base.VariableDoesNotExist: Failed lookup for key [id] in <QueryDict: {}>
Exception while resolving variable 'id' in template 'dash/lms_view.html'.
Traceback (most recent call last):
  File "/opt/xStats/venv/lib64/python3.6/site-packages/django/utils/datastructures.py", line 77, in __getitem__
    list_ = super().__getitem__(key)
KeyError: 'id'

During handling of the above exception, another exception occurred:

Traceback (most recent call last):
  File "/opt/xStats/venv/lib64/python3.6/site-packages/django/template/base.py", line 829, in _resolve_lookup
    current = current[bit]
  File "/opt/xStats/venv/lib64/python3.6/site-packages/django/utils/datastructures.py", line 79, in __getitem__
    raise MultiValueDictKeyError(key)
django.utils.datastructures.MultiValueDictKeyError: 'id'

During handling of the above exception, another exception occurred:

Traceback (most recent call last):
  File "/opt/xStats/venv/lib64/python3.6/site-packages/django/template/base.py", line 837, in _resolve_lookup
    current = getattr(current, bit)
AttributeError: 'QueryDict' object has no attribute 'id'

During handling of the above exception, another exception occurred:

Traceback (most recent call last):
  File "/opt/xStats/venv/lib64/python3.6/site-packages/django/template/base.py", line 843, in _resolve_lookup
    current = current[int(bit)]
ValueError: invalid literal for int() with base 10: 'id'

During handling of the above exception, another exception occurred:

Traceback (most recent call last):
  File "/opt/xStats/venv/lib64/python3.6/site-packages/django/template/base.py", line 850, in _resolve_lookup
    (bit, current))  # missing attribute
django.template.base.VariableDoesNotExist: Failed lookup for key [id] in <QueryDict: {}>
Exception while resolving variable 'id' in template 'dash/lms_view.html'.
Traceback (most recent call last):
  File "/opt/xStats/venv/lib64/python3.6/site-packages/django/utils/datastructures.py", line 77, in __getitem__
    list_ = super().__getitem__(key)
KeyError: 'id'

During handling of the above exception, another exception occurred:

Traceback (most recent call last):
  File "/opt/xStats/venv/lib64/python3.6/site-packages/django/template/base.py", line 829, in _resolve_lookup
    current = current[bit]
  File "/opt/xStats/venv/lib64/python3.6/site-packages/django/utils/datastructures.py", line 79, in __getitem__
    raise MultiValueDictKeyError(key)
django.utils.datastructures.MultiValueDictKeyError: 'id'

During handling of the above exception, another exception occurred:

Traceback (most recent call last):
  File "/opt/xStats/venv/lib64/python3.6/site-packages/django/template/base.py", line 837, in _resolve_lookup
    current = getattr(current, bit)
AttributeError: 'QueryDict' object has no attribute 'id'

During handling of the above exception, another exception occurred:

Traceback (most recent call last):
  File "/opt/xStats/venv/lib64/python3.6/site-packages/django/template/base.py", line 843, in _resolve_lookup
    current = current[int(bit)]
ValueError: invalid literal for int() with base 10: 'id'

During handling of the above exception, another exception occurred:

Traceback (most recent call last):
  File "/opt/xStats/venv/lib64/python3.6/site-packages/django/template/base.py", line 850, in _resolve_lookup
    (bit, current))  # missing attribute
django.template.base.VariableDoesNotExist: Failed lookup for key [id] in <QueryDict: {}>
Exception while resolving variable 'id' in template 'dash/lms_view.html'.
Traceback (most recent call last):
  File "/opt/xStats/venv/lib64/python3.6/site-packages/django/utils/datastructures.py", line 77, in __getitem__
    list_ = super().__getitem__(key)
KeyError: 'id'

During handling of the above exception, another exception occurred:

Traceback (most recent call last):
  File "/opt/xStats/venv/lib64/python3.6/site-packages/django/template/base.py", line 829, in _resolve_lookup
    current = current[bit]
  File "/opt/xStats/venv/lib64/python3.6/site-packages/django/utils/datastructures.py", line 79, in __getitem__
    raise MultiValueDictKeyError(key)
django.utils.datastructures.MultiValueDictKeyError: 'id'

During handling of the above exception, another exception occurred:

Traceback (most recent call last):
  File "/opt/xStats/venv/lib64/python3.6/site-packages/django/template/base.py", line 837, in _resolve_lookup
    current = getattr(current, bit)
AttributeError: 'QueryDict' object has no attribute 'id'

During handling of the above exception, another exception occurred:

Traceback (most recent call last):
  File "/opt/xStats/venv/lib64/python3.6/site-packages/django/template/base.py", line 843, in _resolve_lookup
    current = current[int(bit)]
ValueError: invalid literal for int() with base 10: 'id'

During handling of the above exception, another exception occurred:

Traceback (most recent call last):
  File "/opt/xStats/venv/lib64/python3.6/site-packages/django/template/base.py", line 850, in _resolve_lookup
    (bit, current))  # missing attribute
django.template.base.VariableDoesNotExist: Failed lookup for key [id] in <QueryDict: {}>
Exception while resolving variable 'id' in template 'dash/lms_view.html'.
Traceback (most recent call last):
  File "/opt/xStats/venv/lib64/python3.6/site-packages/django/utils/datastructures.py", line 77, in __getitem__
    list_ = super().__getitem__(key)
KeyError: 'id'

During handling of the above exception, another exception occurred:

Traceback (most recent call last):
  File "/opt/xStats/venv/lib64/python3.6/site-packages/django/template/base.py", line 829, in _resolve_lookup
    current = current[bit]
  File "/opt/xStats/venv/lib64/python3.6/site-packages/django/utils/datastructures.py", line 79, in __getitem__
    raise MultiValueDictKeyError(key)
django.utils.datastructures.MultiValueDictKeyError: 'id'

During handling of the above exception, another exception occurred:

Traceback (most recent call last):
  File "/opt/xStats/venv/lib64/python3.6/site-packages/django/template/base.py", line 837, in _resolve_lookup
    current = getattr(current, bit)
AttributeError: 'QueryDict' object has no attribute 'id'

During handling of the above exception, another exception occurred:

Traceback (most recent call last):
  File "/opt/xStats/venv/lib64/python3.6/site-packages/django/template/base.py", line 843, in _resolve_lookup
    current = current[int(bit)]
ValueError: invalid literal for int() with base 10: 'id'

During handling of the above exception, another exception occurred:

Traceback (most recent call last):
  File "/opt/xStats/venv/lib64/python3.6/site-packages/django/template/base.py", line 850, in _resolve_lookup
    (bit, current))  # missing attribute
django.template.base.VariableDoesNotExist: Failed lookup for key [id] in <QueryDict: {}>
Exception while resolving variable 'id' in template 'dash/lms_view.html'.
Traceback (most recent call last):
  File "/opt/xStats/venv/lib64/python3.6/site-packages/django/utils/datastructures.py", line 77, in __getitem__
    list_ = super().__getitem__(key)
KeyError: 'id'

During handling of the above exception, another exception occurred:

Traceback (most recent call last):
  File "/opt/xStats/venv/lib64/python3.6/site-packages/django/template/base.py", line 829, in _resolve_lookup
    current = current[bit]
  File "/opt/xStats/venv/lib64/python3.6/site-packages/django/utils/datastructures.py", line 79, in __getitem__
    raise MultiValueDictKeyError(key)
django.utils.datastructures.MultiValueDictKeyError: 'id'

During handling of the above exception, another exception occurred:

Traceback (most recent call last):
  File "/opt/xStats/venv/lib64/python3.6/site-packages/django/template/base.py", line 837, in _resolve_lookup
    current = getattr(current, bit)
AttributeError: 'QueryDict' object has no attribute 'id'

During handling of the above exception, another exception occurred:

Traceback (most recent call last):
  File "/opt/xStats/venv/lib64/python3.6/site-packages/django/template/base.py", line 843, in _resolve_lookup
    current = current[int(bit)]
ValueError: invalid literal for int() with base 10: 'id'

During handling of the above exception, another exception occurred:

Traceback (most recent call last):
  File "/opt/xStats/venv/lib64/python3.6/site-packages/django/template/base.py", line 850, in _resolve_lookup
    (bit, current))  # missing attribute
django.template.base.VariableDoesNotExist: Failed lookup for key [id] in <QueryDict: {}>
Exception while resolving variable 'id' in template 'dash/lms_view.html'.
Traceback (most recent call last):
  File "/opt/xStats/venv/lib64/python3.6/site-packages/django/utils/datastructures.py", line 77, in __getitem__
    list_ = super().__getitem__(key)
KeyError: 'id'

During handling of the above exception, another exception occurred:

Traceback (most recent call last):
  File "/opt/xStats/venv/lib64/python3.6/site-packages/django/template/base.py", line 829, in _resolve_lookup
    current = current[bit]
  File "/opt/xStats/venv/lib64/python3.6/site-packages/django/utils/datastructures.py", line 79, in __getitem__
    raise MultiValueDictKeyError(key)
django.utils.datastructures.MultiValueDictKeyError: 'id'

During handling of the above exception, another exception occurred:

Traceback (most recent call last):
  File "/opt/xStats/venv/lib64/python3.6/site-packages/django/template/base.py", line 837, in _resolve_lookup
    current = getattr(current, bit)
AttributeError: 'QueryDict' object has no attribute 'id'

During handling of the above exception, another exception occurred:

Traceback (most recent call last):
  File "/opt/xStats/venv/lib64/python3.6/site-packages/django/template/base.py", line 843, in _resolve_lookup
    current = current[int(bit)]
ValueError: invalid literal for int() with base 10: 'id'

During handling of the above exception, another exception occurred:

Traceback (most recent call last):
  File "/opt/xStats/venv/lib64/python3.6/site-packages/django/template/base.py", line 850, in _resolve_lookup
    (bit, current))  # missing attribute
django.template.base.VariableDoesNotExist: Failed lookup for key [id] in <QueryDict: {}>
Exception while resolving variable 'id' in template 'dash/lms_view.html'.
Traceback (most recent call last):
  File "/opt/xStats/venv/lib64/python3.6/site-packages/django/utils/datastructures.py", line 77, in __getitem__
    list_ = super().__getitem__(key)
KeyError: 'id'

During handling of the above exception, another exception occurred:

Traceback (most recent call last):
  File "/opt/xStats/venv/lib64/python3.6/site-packages/django/template/base.py", line 829, in _resolve_lookup
    current = current[bit]
  File "/opt/xStats/venv/lib64/python3.6/site-packages/django/utils/datastructures.py", line 79, in __getitem__
    raise MultiValueDictKeyError(key)
django.utils.datastructures.MultiValueDictKeyError: 'id'

During handling of the above exception, another exception occurred:

Traceback (most recent call last):
  File "/opt/xStats/venv/lib64/python3.6/site-packages/django/template/base.py", line 837, in _resolve_lookup
    current = getattr(current, bit)
AttributeError: 'QueryDict' object has no attribute 'id'

During handling of the above exception, another exception occurred:

Traceback (most recent call last):
  File "/opt/xStats/venv/lib64/python3.6/site-packages/django/template/base.py", line 843, in _resolve_lookup
    current = current[int(bit)]
ValueError: invalid literal for int() with base 10: 'id'

During handling of the above exception, another exception occurred:

Traceback (most recent call last):
  File "/opt/xStats/venv/lib64/python3.6/site-packages/django/template/base.py", line 850, in _resolve_lookup
    (bit, current))  # missing attribute
django.template.base.VariableDoesNotExist: Failed lookup for key [id] in <QueryDict: {}>
Exception while resolving variable 'id' in template 'dash/lms_view.html'.
Traceback (most recent call last):
  File "/opt/xStats/venv/lib64/python3.6/site-packages/django/utils/datastructures.py", line 77, in __getitem__
    list_ = super().__getitem__(key)
KeyError: 'id'

During handling of the above exception, another exception occurred:

Traceback (most recent call last):
  File "/opt/xStats/venv/lib64/python3.6/site-packages/django/template/base.py", line 829, in _resolve_lookup
    current = current[bit]
  File "/opt/xStats/venv/lib64/python3.6/site-packages/django/utils/datastructures.py", line 79, in __getitem__
    raise MultiValueDictKeyError(key)
django.utils.datastructures.MultiValueDictKeyError: 'id'

During handling of the above exception, another exception occurred:

Traceback (most recent call last):
  File "/opt/xStats/venv/lib64/python3.6/site-packages/django/template/base.py", line 837, in _resolve_lookup
    current = getattr(current, bit)
AttributeError: 'QueryDict' object has no attribute 'id'

During handling of the above exception, another exception occurred:

Traceback (most recent call last):
  File "/opt/xStats/venv/lib64/python3.6/site-packages/django/template/base.py", line 843, in _resolve_lookup
    current = current[int(bit)]
ValueError: invalid literal for int() with base 10: 'id'

During handling of the above exception, another exception occurred:

Traceback (most recent call last):
  File "/opt/xStats/venv/lib64/python3.6/site-packages/django/template/base.py", line 850, in _resolve_lookup
    (bit, current))  # missing attribute
django.template.base.VariableDoesNotExist: Failed lookup for key [id] in <QueryDict: {}>
Exception while resolving variable 'id' in template 'dash/lms_view.html'.
Traceback (most recent call last):
  File "/opt/xStats/venv/lib64/python3.6/site-packages/django/utils/datastructures.py", line 77, in __getitem__
    list_ = super().__getitem__(key)
KeyError: 'id'

During handling of the above exception, another exception occurred:

Traceback (most recent call last):
  File "/opt/xStats/venv/lib64/python3.6/site-packages/django/template/base.py", line 829, in _resolve_lookup
    current = current[bit]
  File "/opt/xStats/venv/lib64/python3.6/site-packages/django/utils/datastructures.py", line 79, in __getitem__
    raise MultiValueDictKeyError(key)
django.utils.datastructures.MultiValueDictKeyError: 'id'

During handling of the above exception, another exception occurred:

Traceback (most recent call last):
  File "/opt/xStats/venv/lib64/python3.6/site-packages/django/template/base.py", line 837, in _resolve_lookup
    current = getattr(current, bit)
AttributeError: 'QueryDict' object has no attribute 'id'

During handling of the above exception, another exception occurred:

Traceback (most recent call last):
  File "/opt/xStats/venv/lib64/python3.6/site-packages/django/template/base.py", line 843, in _resolve_lookup
    current = current[int(bit)]
ValueError: invalid literal for int() with base 10: 'id'

During handling of the above exception, another exception occurred:

Traceback (most recent call last):
  File "/opt/xStats/venv/lib64/python3.6/site-packages/django/template/base.py", line 850, in _resolve_lookup
    (bit, current))  # missing attribute
django.template.base.VariableDoesNotExist: Failed lookup for key [id] in <QueryDict: {}>
